Workbook
Name Slicer_GENRE: #N/A
Name Slicer_LANGUAGE: #N/A
Name Slicer_RATING_TIER: #N/A
Name Slicer_YEAR: #N/A

Sheet Cleaned Data
A1: BOOK INSIGHT EXPLORER: Analyzing Reader Trends and Genre Preferences
A4: CLEANED DATA FOR ANALYSIS
A5: TITLE | B5: AUTHOR | C5: PAGES | D5: GENRE | E5: PUBLISHED DATE | F5: PUBLISHER | G5: LANGUAGE | H5: AVERAGE RATING | I5: RATINGS COUNT | J5: YEAR | K5: RATING TIER | L5: POPULARITY | M5: ENGAGEMENT SCORE
A6: Fictional Points of View | B6: Peter Lamarque | C6: 252 | D6: Literary Criticism | E6: 01-01-1996 | F6: Cornell University Press | G6: en | H6: 0 | I6: 0 | J6: 1996 | K6: =IF(Books[[#This Row],[AVERAGE RATING]]>=4,"High",IF(Books[[#This Row],[AVERAGE RATING]]>=3,"Medium","Low")) -> Low | L6: =IF(Books[[#This Row],[AVERAGE RATING]]>10000,"Popular","Average") -> Average | M6: =Books[[#This Row],[AVERAGE RATING]]*Books[[#This Row],[RATINGS COUNT]] -> 0
A7: Science Fiction and Fantasy Literature | B7: R. Reginald, Douglas Menville, Mary A. Burgess | C7: 802 | D7: Reference | E7: 01-09-2010 | F7: Wildside Press LLC | G7: en | H7: 0 | I7: 0 | J7: 2010 | K7: =IF(Books[[#This Row],[AVERAGE RATING]]>=4,"High",IF(Books[[#This Row],[AVERAGE RATING]]>=3,"Medium","Low")) -> Low | L7: =IF(Books[[#This Row],[AVERAGE RATING]]>10000,"Popular","Average") -> Average | M7: =Books[[#This Row],[AVERAGE RATING]]*Books[[#This Row],[RATINGS COUNT]] -> 0
A8: Fictional Space in the Modernist and Post-modernist American Novel | B8: Carl Darryl Malmgren | C8: 248 | D8: Fiction | E8: 01-01-1985 | F8: Bucknell University Press | G8: en | H8: 0 | I8: 0 | J8: 1985 | K8: =IF(Books[[#This Row],[AVERAGE RATING]]>=4,"High",IF(Books[[#This Row],[AVERAGE RATING]]>=3,"Medium","Low")) -> Low | L8: =IF(Books[[#This Row],[AVERAGE RATING]]>10000,"Popular","Average") -> Average | M8: =Books[[#This Row],[AVERAGE RATING]]*Books[[#This Row],[RATINGS COUNT]] -> 0
A9: Mestizos Come Home! | B9: Robert Con Davis-Undiano | C9: 337 | D9: History | E9: 30-03-2017 | F9: University of Oklahoma Press | G9: en | H9: 0 | I9: 0 | J9: 2017 | K9: =IF(Books[[#This Row],[AVERAGE RATING]]>=4,"High",IF(Books[[#This Row],[AVERAGE RATING]]>=3,"Medium","Low")) -> Low | L9: =IF(Books[[#This Row],[AVERAGE RATING]]>10000,"Popular","Average") -> Average | M9: =Books[[#This Row],[AVERAGE RATING]]*Books[[#This Row],[RATINGS COUNT]] -> 0
A10: Telling Lies in Modern American Autobiography | B10: Timothy Dow Adams | C10: 230 | D10: Literary Criticism | E10: 01-01-1990 | F10: UNC Press Books | G10: en | H10: 0 | I10: 0 | J10: 1990 | K10: =IF(Books[[#This Row],[AVERAGE RATING]]>=4,"High",IF(Books[[#This Row],[AVERAGE RATING]]>=3,"Medium","Low")) -> Low | L10: =IF(Books[[#This Row],[AVERAGE RATING]]>10000,"Popular","Average") -> Average | M10: =Books[[#This Row],[AVERAGE RATING]]*Books[[#This Row],[RATINGS COUNT]] -> 0
A11: Essential Skills - Reading and Writing, Grade 1 | B11: Teacher Created Resources, Inc | C11: 178 | D11: Activity programs in education | E11: 01-12-2008 | F11: Teacher Created Resources | G11: en | H11: 0 | I11: 0 | J11: 2008 | K11: =IF(Books[[#This Row],[AVERAGE RATING]]>=4,"High",IF(Books[[#This Row],[AVERAGE RATING]]>=3,"Medium","Low")) -> Low | L11: =IF(Books[[#This Row],[AVERAGE RATING]]>10000,"Popular","Average") -> Average | M11: =Books[[#This Row],[AVERAGE RATING]]*Books[[#This Row],[RATINGS COUNT]] -> 0
A12: Reload | B12: Mary Flanagan, Austin Booth | C12: 604 | D12: Social Science | E12: 03-05-2002 | F12: MIT Press | G12: en | H12: 0 | I12: 0 | J12: 2002 | K12: =IF(Books[[#This Row],[AVERAGE RATING]]>=4,"High",IF(Books[[#This Row],[AVERAGE RATING]]>=3,"Medium","Low")) -> Low | L12: =IF(Books[[#This Row],[AVERAGE RATING]]>10000,"Popular","Average") -> Average | M12: =Books[[#This Row],[AVERAGE RATING]]*Books[[#This Row],[RATINGS COUNT]] -> 0
A13: Presented Discourse in Popular Science | B13: Olga Pilkington | C13: 206 | D13: Language Arts & Disciplines | E13: 03-07-2018 | F13: BRILL | G13: en | H13: 0 | I13: 0 | J13: 2018 | K13: =IF(Books[[#This Row],[AVERAGE RATING]]>=4,"High",IF(Books[[#This Row],[AVERAGE RATING]]>=3,"Medium","Low")) -> Low | L13: =IF(Books[[#This Row],[AVERAGE RATING]]>10000,"Popular","Average") -> Average | M13: =Books[[#This Row],[AVERAGE RATING]]*Books[[#This Row],[RATINGS COUNT]] -> 0
A14: Encyclopedia of the Novel | B14: Paul Schellinger | C14: 838 | D14: Literary Criticism | E14: 08-04-2014 | F14: Routledge | G14: en | H14: 3 | I14: 2 | J14: 2014 | K14: =IF(Books[[#This Row],[AVERAGE RATING]]>=4,"High",IF(Books[[#This Row],[AVERAGE RATING]]>=3,"Medium","Low")) -> Medium | L14: =IF(Books[[#This Row],[AVERAGE RATING]]>10000,"Popular","Average") -> Average | M14: =Books[[#This Row],[AVERAGE RATING]]*Books[[#This Row],[RATINGS COUNT]] -> 6
A15: Idealism | B15: Tyron Goldschmidt, Kenneth L. Pearce | C15: 314 | D15: Philosophy | E15: 01-01-2017 | F15: Oxford University Press | G15: en | H15: 0 | I15: 0 | J15: 2017 | K15: =IF(Books[[#This Row],[AVERAGE RATING]]>=4,"High",IF(Books[[#This Row],[AVERAGE RATING]]>=3,"Medium","Low")) -> Low | L15: =IF(Books[[#This Row],[AVERAGE RATING]]>10000,"Popular","Average") -> Average | M15: =Books[[#This Row],[AVERAGE RATING]]*Books[[#This Row],[RATINGS COUNT]] -> 0
A16: The Philosophy of David Cronenberg | B16: Simon Riches | C16: 234 | D16: Philosophy | E16: 20-04-2012 | F16: University Press of Kentucky | G16: en | H16: 0 | I16: 0 | J16: 2012 | K16: =IF(Books[[#This Row],[AVERAGE RATING]]>=4,"High",IF(Books[[#This Row],[AVERAGE RATING]]>=3,"Medium","Low")) -> Low | L16: =IF(Books[[#This Row],[AVERAGE RATING]]>10000,"Popular","Average") -> Average | M16: =Books[[#This Row],[AVERAGE RATING]]*Books[[#This Row],[RATINGS COUNT]] -> 0
A17: International Who's Who of Authors and Writers 2004 | B17: Europa Publications | C17: 644 | D17: Biography & Autobiography | E17: 01-01-2003 | F17: Psychology Press | G17: en | H17: 0 | I17: 0 | J17: 2003 | K17: =IF(Books[[#This Row],[AVERAGE RATING]]>=4,"High",IF(Books[[#This Row],[AVERAGE RATING]]>=3,"Medium","Low")) -> Low | L17: =IF(Books[[#This Row],[AVERAGE RATING]]>10000,"Popular","Average") -> Average | M17: =Books[[#This Row],[AVERAGE RATING]]*Books[[#This Row],[RATINGS COUNT]] -> 0
... A207: Handbook of Clinical Psychopharmacology for Psychologists | B207: Mark Muse, Bret A. Moore | C207: 532 | D207: Psychology | E207: 22-03-2012 | F207: John Wiley & Sons | G207: en | H207: 0 | I207: 0 | J207: 2012 | K207: =IF(Books[[#This Row],[AVERAGE RATING]]>=4,"High",IF(Books[[#This Row],[AVERAGE RATING]]>=3,"Medium","Low")) -> Low | L207: =IF(Books[[#This Row],[AVERAGE RATING]]>10000,"Popular","Average") -> Average | M207: =Books[[#This Row],[AVERAGE RATING]]*Books[[#This Row],[RATINGS COUNT]] -> 0
A208: What Is Psychology? | B208: Ellen E. Pastorino, Susann M. Doyle-Portillo | D208: Psychology | E208: 07-01-2020 | F208: Cengage Learning | G208: en | H208: 0 | I208: 0 | J208: 2020 | K208: =IF(Books[[#This Row],[AVERAGE RATING]]>=4,"High",IF(Books[[#This Row],[AVERAGE RATING]]>=3,"Medium","Low")) -> Low | L208: =IF(Books[[#This Row],[AVERAGE RATING]]>10000,"Popular","Average") -> Average | M208: =Books[[#This Row],[AVERAGE RATING]]*Books[[#This Row],[RATINGS COUNT]] -> 0
A209: The Future of Psychology | B209: Rubén Ardila | C209: 260 | D209: Psychology | E209: 14-03-2025 | F209: Springer Nature | G209: en | H209: 0 | I209: 0 | J209: 2025 | K209: =IF(Books[[#This Row],[AVERAGE RATING]]>=4,"High",IF(Books[[#This Row],[AVERAGE RATING]]>=3,"Medium","Low")) -> Low | L209: =IF(Books[[#This Row],[AVERAGE RATING]]>10000,"Popular","Average") -> Average | M209: =Books[[#This Row],[AVERAGE RATING]]*Books[[#This Row],[RATINGS COUNT]] -> 0
A210: The Psychological Science of Money | B210: Erik Bijleveld, Henk Aarts | C210: 267 | D210: Psychology | E210: 10-07-2014 | F210: Springer | G210: en | H210: 0 | I210: 0 | J210: 2014 | K210: =IF(Books[[#This Row],[AVERAGE RATING]]>=4,"High",IF(Books[[#This Row],[AVERAGE RATING]]>=3,"Medium","Low")) -> Low | L210: =IF(Books[[#This Row],[AVERAGE RATING]]>10000,"Popular","Average") -> Average | M210: =Books[[#This Row],[AVERAGE RATING]]*Books[[#This Row],[RATINGS COUNT]] -> 0
A211: Meta-Analysis for Psychologists | B211: Richard Cooke | C211: 194 | D211: Psychology | E211: 23-12-2024 | F211: Springer Nature | G211: en | H211: 0 | I211: 0 | J211: 2024 | K211: =IF(Books[[#This Row],[AVERAGE RATING]]>=4,"High",IF(Books[[#This Row],[AVERAGE RATING]]>=3,"Medium","Low")) -> Low | L211: =IF(Books[[#This Row],[AVERAGE RATING]]>10000,"Popular","Average") -> Average | M211: =Books[[#This Row],[AVERAGE RATING]]*Books[[#This Row],[RATINGS COUNT]] -> 0
A212: Foundations of the Psychological Intervention | B212: Sergio Salvatore, Barbara Cordella | C212: 235 | D212: Psychology | E212: 03-04-2024 | F212: Taylor & Francis | G212: en | H212: 0 | I212: 0 | J212: 2024 | K212: =IF(Books[[#This Row],[AVERAGE RATING]]>=4,"High",IF(Books[[#This Row],[AVERAGE RATING]]>=3,"Medium","Low")) -> Low | L212: =IF(Books[[#This Row],[AVERAGE RATING]]>10000,"Popular","Average") -> Average | M212: =Books[[#This Row],[AVERAGE RATING]]*Books[[#This Row],[RATINGS COUNT]] -> 0
A213: Essentials of Culture in Psychological Assessment | B213: A. Jordan Wright | C213: 566 | D213: Psychology | E213: 05-11-2024 | F213: John Wiley & Sons | G213: en | H213: 0 | I213: 0 | J213: 2024 | K213: =IF(Books[[#This Row],[AVERAGE RATING]]>=4,"High",IF(Books[[#This Row],[AVERAGE RATING]]>=3,"Medium","Low")) -> Low | L213: =IF(Books[[#This Row],[AVERAGE RATING]]>10000,"Popular","Average") -> Average | M213: =Books[[#This Row],[AVERAGE RATING]]*Books[[#This Row],[RATINGS COUNT]] -> 0
A214: Essays in Ancient Greek Philosophy II | B214: John Peter Anton, George L. Kustas, Anthony Preus | C214: 572 | D214: Philosophy | E214: 01-01-1971 | F214: SUNY Press | G214: en | H214: 0 | I214: 0 | J214: 1971 | K214: =IF(Books[[#This Row],[AVERAGE RATING]]>=4,"High",IF(Books[[#This Row],[AVERAGE RATING]]>=3,"Medium","Low")) -> Low | L214: =IF(Books[[#This Row],[AVERAGE RATING]]>10000,"Popular","Average") -> Average | M214: =Books[[#This Row],[AVERAGE RATING]]*Books[[#This Row],[RATINGS COUNT]] -> 0
A215: Behavior and Psychological Man | B215: Edward Chace Tolman | C215: 286 | D215: Psychology | E215: 15-11-2023 | F215: Univ of California Press | G215: en | H215: 0 | I215: 0 | J215: 2023 | K215: =IF(Books[[#This Row],[AVERAGE RATING]]>=4,"High",IF(Books[[#This Row],[AVERAGE RATING]]>=3,"Medium","Low")) -> Low | L215: =IF(Books[[#This Row],[AVERAGE RATING]]>10000,"Popular","Average") -> Average | M215: =Books[[#This Row],[AVERAGE RATING]]*Books[[#This Row],[RATINGS COUNT]] -> 0
A216: Dissemination and Implementation of Evidence-Based Psychological Interventions | B216: R. Kathryn McHugh, David H. Barlow | C216: 289 | D216: Psychology | E216: 15-04-2012 | F216: Oxford University Press | G216: en | H216: 0 | I216: 0 | J216: 2012 | K216: =IF(Books[[#This Row],[AVERAGE RATING]]>=4,"High",IF(Books[[#This Row],[AVERAGE RATING]]>=3,"Medium","Low")) -> Low | L216: =IF(Books[[#This Row],[AVERAGE RATING]]>10000,"Popular","Average") -> Average | M216: =Books[[#This Row],[AVERAGE RATING]]*Books[[#This Row],[RATINGS COUNT]] -> 0
A217: Psychology Australian and New Zealand Edition | B217: Douglas A. Bernstein, Julie Ann Pooley, Lynne Cohen, Steve Provost, Jacquelyn Cranney, Bethanie Gouldthorp, Neil Drew | C217: 57 | D217: Psychology | E217: 05-10-2020 | F217: Cengage AU | G217: en | H217: 0 | I217: 0 | J217: 2020 | K217: =IF(Books[[#This Row],[AVERAGE RATING]]>=4,"High",IF(Books[[#This Row],[AVERAGE RATING]]>=3,"Medium","Low")) -> Low | L217: =IF(Books[[#This Row],[AVERAGE RATING]]>10000,"Popular","Average") -> Average | M217: =Books[[#This Row],[AVERAGE RATING]]*Books[[#This Row],[RATINGS COUNT]] -> 0
A218: Essentials of Forensic Psychological Assessment | B218: Marc J. Ackerman | C218: 357 | D218: Psychology | E218: 06-04-2010 | F218: John Wiley & Sons | G218: en | H218: 0 | I218: 0 | J218: 2010 | K218: =IF(Books[[#This Row],[AVERAGE RATING]]>=4,"High",IF(Books[[#This Row],[AVERAGE RATING]]>=3,"Medium","Low")) -> Low | L218: =IF(Books[[#This Row],[AVERAGE RATING]]>10000,"Popular","Average") -> Average | M218: =Books[[#This Row],[AVERAGE RATING]]*Books[[#This Row],[RATINGS COUNT]] -> 0
A219: Emotions in Social Psychology | B219: W. Gerrod Parrott | C219: 402 | D219: Psychology | E219: 01-01-2001 | F219: Psychology Press | G219: en | H219: 5 | I219: 1 | J219: 2001 | K219: =IF(Books[[#This Row],[AVERAGE RATING]]>=4,"High",IF(Books[[#This Row],[AVERAGE RATING]]>=3,"Medium","Low")) -> High | L219: =IF(Books[[#This Row],[AVERAGE RATING]]>10000,"Popular","Average") -> Average | M219: =Books[[#This Row],[AVERAGE RATING]]*Books[[#This Row],[RATINGS COUNT]] -> 5
A220: Pyschology 4e | B220: Douglas A. Bernstein, Julie Ann Pooley, Lynne Cohen, Steve Provost, Jacquelyn Cranney, Neil Drew | C220: 57 | D220: Psychology | E220: 03-11-2023 | F220: Cengage AU | G220: en | H220: 0 | I220: 0 | J220: 2023 | K220: =IF(Books[[#This Row],[AVERAGE RATING]]>=4,"High",IF(Books[[#This Row],[AVERAGE RATING]]>=3,"Medium","Low")) -> Low | L220: =IF(Books[[#This Row],[AVERAGE RATING]]>10000,"Popular","Average") -> Average | M220: =Books[[#This Row],[AVERAGE RATING]]*Books[[#This Row],[RATINGS COUNT]] -> 0
... A1388: The Money Manual | B1388: Tonya Rapley | C1388: 256 | D1388: Personal Finance | E1388: 16-05-2023 | F1388: Adams Media | G1388: en | H1388: 4.2 | I1388: 20000 | J1388: 2023 | K1388: =IF(Books[[#This Row],[AVERAGE RATING]]>=4,"High",IF(Books[[#This Row],[AVERAGE RATING]]>=3,"Medium","Low")) -> High | L1388: =IF(Books[[#This Row],[AVERAGE RATING]]>10000,"Popular","Average") -> Average | M1388: =Books[[#This Row],[AVERAGE RATING]]*Books[[#This Row],[RATINGS COUNT]] -> 84000

Sheet Pivot Tables
A1: BOOK COUNT BY GENRE | F1: PUBLICATION TRENDS | J1: AVERAGE RATINGS PER GENER | M1: TOP 10 AUTHORS BY BOOK COUNT | Q1: LANGUAGE BREAKDOWN | U1: READER ENGAGEMENT
A4: Row Labels | B4: Count of TITLE | F4: Row Labels | G4: Count of TITLE | J4: Row Labels | K4: Average of AVERAGE RATING | M4: Row Labels | N4: Count of TITLE | Q4: Row Labels | R4: Count of TITLE | U4: Row Labels | V4: Sum of ENGAGEMENT SCORE
A5: Activity programs in education | B5: 1 | F5: 1887 | G5: 1 | J5: Activity programs in education | K5: 0 | M5: Stephen King | N5: 22 | Q5: cs | R5: 3 | U5: Rich Dad Poor Dad | V5: 4100000
A6: Africans in literature | B6: 1 | F6: 1888 | G6: 1 | J6: Africans in literature | K6: 0 | M6: Agatha Christie | N6: 22 | Q6: el | R6: 2 | U6: Atomic Habits | V6: 3080000
A7: American literature | B7: 1 | F7: 1894 | G7: 1 | J7: American literature | K7: 4 | M7: Dan Brown | N7: 21 | Q7: en | R7: 1311 | U7: The 7 Habits of Highly Effective People | V7: 2940000
A8: Antiques & Collectibles | B8: 3 | F8: 1900 | G8: 1 | J8: Antiques & Collectibles | K8: 0 | M8: Sir Arthur Conan Doyle | N8: 11 | Q8: es | R8: 10 | U8: Think and Grow Rich | V8: 2580000
A9: Architecture | B9: 2 | F9: 1902 | G9: 1 | J9: Architecture | K9: 0 | M9: Arthur Conan Doyle | N9: 11 | Q9: fr | R9: 2 | U9: The Richest Man in Babylon | V9: 1720000
A10: Art | B10: 31 | F10: 1907 | G10: 1 | J10: Art | K10: 0.22580645 | M10: George Orwell | N10: 11 | Q10: hi | R10: 1 | U10: The Total Money Makeover | V10: 1680000
A11: Authors, English | B11: 1 | F11: 1910 | G11: 2 | J11: Authors, English | K11: 0 | M11: Harold Bloom | N11: 9 | Q11: hu | R11: 1 | U11: The 4-Hour Workweek | V11: 1640000
A12: Bananas | B12: 1 | F12: 1911 | G12: 1 | J12: Bananas | K12: 0 | M12: Lewis Carroll | N12: 9 | Q12: id | R12: 19 | U12: Mindset: The New Psychology of Success | V12: 1260000
A13: Biography & Autobiography | B13: 55 | F13: 1926 | G13: 1 | J13: Biography & Autobiography | K13: 0.41818182 | M13: Suzanne Collins | N13: 8 | Q13: it | R13: 13 | U13: The Millionaire Next Door | V13: 1230000
A14: Body, Mind & Spirit | B14: 6 | F14: 1937 | G14: 1 | J14: Body, Mind & Spirit | K14: 0 | M14: Carole Marsh | N14: 7 | Q14: ko | R14: 1 | U14: The Psychology of Money | V14: 1075000
A15: Business & Economics | B15: 43 | F15: 1949 | G15: 1 | J15: Business & Economics | K15: 0.58139535 | M15: Blake Pierce | N15: 7 | Q15: mr | R15: 1 | U15: Grand Total | V15: 21305000
A16: Canadian fiction | B16: 1 | F16: 1960 | G16: 1 | J16: Canadian fiction | K16: 0 | M16: Grand Total | N16: 138 | Q16: ms | R16: 2
A17: Cape Town (South Africa) | B17: 1 | F17: 1967 | G17: 1 | J17: Cape Town (South Africa) | K17: 0 | Q17: ne | R17: 1
A18: Cell phones | B18: 1 | F18: 1969 | G18: 1 | J18: Cell phones | K18: 4 | Q18: no | R18: 2
A19: Children | B19: 1 | F19: 1970 | G19: 1 | J19: Children | K19: 3 | Q19: pl | R19: 1
A20: Children with visual disabilities | B20: 1 | F20: 1971 | G20: 3 | J20: Children with visual disabilities | K20: 0 | Q20: pt | R20: 7
A21: Children's stories | B21: 1 | F21: 1972 | G21: 2 | J21: Children's stories | K21: 4.5 | Q21: sv | R21: 1
A22: Children's stories, English | B22: 1 | F22: 1973 | G22: 1 | J22: Children's stories, English | K22: 5 | Q22: tr | R22: 4
A23: Comics & Graphic Novels | B23: 11 | F23: 1977 | G23: 1 | J23: Comics & Graphic Novels | K23: 0 | Q23: zh-TW | R23: 1
A24: Computers | B24: 22 | F24: 1978 | G24: 1 | J24: Computers | K24: 0.84090909 | Q24: Grand Total | R24: 1383
A25: Cooking | B25: 4 | F25: 1980 | G25: 1 | J25: Cooking | K25: 0
A26: Cooking, Indic | B26: 1 | F26: 1982 | G26: 3 | J26: Cooking, Indic | K26: 5
A27: Crafts & Hobbies | B27: 3 | F27: 1983 | G27: 3 | J27: Crafts & Hobbies | K27: 0
A28: Creation in literature | B28: 1 | F28: 1985 | G28: 3 | J28: Creation in literature | K28: 0
A29: Criticism | B29: 3 | F29: 1986 | G29: 3 | J29: Criticism | K29: 0
A30: Dance | B30: 1 | F30: 1987 | G30: 3 | J30: Dance | K30: 0
A31: Drama | B31: 19 | F31: 1988 | G31: 4 | J31: Drama | K31: 0.78947368
A32: Dystopias in literature | B32: 2 | F32: 1989 | G32: 8 | J32: Dystopias in literature | K32: 2
A33: Education | B33: 68 | F33: 1990 | G33: 2 | J33: Education | K33: 0.26470588
A34: Electronic data processing | B34: 1 | F34: 1991 | G34: 3 | J34: Electronic data processing | K34: 0
A35: English literature | B35: 1 | F35: 1992 | G35: 3 | J35: English literature | K35: 0
A36: Ethics | B36: 1 | F36: 1993 | G36: 7 | J36: Ethics | K36: 0
... A68: Religion | B68: 38 | F68: 2025 | G68: 32 | J68: Religion | K68: 0.23684211
A69: Science | B69: 34 | F69: Grand Total | G69: 1383 | J69: Science | K69: 0.63235294
A70: Self-Help | B70: 16 | J70: Self-Help | K70: 2.64375
A71: Social Science | B71: 60 | J71: Social Science | K71: 0.15833333
A72: Sonnets, English | B72: 1 | J72: Sonnets, English | K72: 5
A73: Sports & Recreation | B73: 4 | J73: Sports & Recreation | K73: 1.125
...

Sheet KPI CREATION
B2: Total Number of Books | F2: =COUNTA(Books[TITLE]) -> 1383 | M2: KPI BOOK COUNT
M3: =GETPIVOTDATA("TITLE",'Pivot Tables'!$A$4) -> 1383
B5: Total Unique Authors | F5: =COUNTA(_xlfn.UNIQUE(Books[AUTHOR])) -> 1138 | M5: KPI UNIQUE AUTHORS
M6: =COUNTA('Pivot Tables'!N5:N15) -> 11
B8: Average Rating | F8: =AVERAGE(Books[AVERAGE RATING]) -> 0.6308026 | M8: KPI AVERAGE RATING
M9: =GETPIVOTDATA("AVERAGE RATING",'Pivot Tables'!$J$4) -> 0.6308026
B11: Highest Rated Book | F11: =_xlfn.XLOOKUP(MAX(Books[AVERAGE RATING]),Books[AVERAGE RATING],Books[TITLE]) -> International Encyclopedia of Linguistics | M11: KPI HIGHEST RATED BOOK
M12: =INDEX('Pivot Tables'!U5:U14,MATCH(MAX('Pivot Tables'!V5:V14),'Pivot Tables'!V5:V14, 0)) -> Rich Dad Poor Dad
B14: Most Common Language | F14: {=INDEX(_xlfn.SORTBY(_xlfn.UNIQUE(Books[LANGUAGE]),-COUNTIF(Books[LANGUAGE],_xlfn.UNIQUE(Books[LANGUAGE]))), 1)} -> en | M14: KPI MOST COMMON LANGUAGE
M15: =INDEX('Pivot Tables'!Q5:Q23,MATCH(MAX('Pivot Tables'!R5:R23),'Pivot Tables'!R5:R23, 0)) -> en
B17: Total Reader Engagement Score | F17: =SUM(Books[ENGAGEMENT SCORE]) -> 31892556 | M17: KPI ENGAGEMENT SCORE
M18: =GETPIVOTDATA("ENGAGEMENT SCORE",'Pivot Tables'!$U$4) -> 21305000
B20: Most Popular Genre | F20: {=INDEX(_xlfn.SORTBY(_xlfn.UNIQUE(Books[GENRE]),-COUNTIF(Books[GENRE],_xlfn.UNIQUE(Books[GENRE]))), 1)} -> Fiction | M20: KPI MOST POPULAR GENRE
M21: =INDEX('Pivot Tables'!A5:A78,MATCH(MAX('Pivot Tables'!B5:B78),'Pivot Tables'!B5:B78,0)) -> Fiction
C27: FROM THE ORIGINAL DATA CANNOT BE DYNAMIC | M27: FROM THE PIVOT TABLE THAT IS DYNAMICALLY CHANGE THE VALUE THROUGH SLICERS

Sheet  EMO ND SUMMARY
C4: 📚 | E4: 👤 | G4: ⭐ | I4: 🏆 | K4: 🎭 | M4: 🔥 | O4: 🌏 | Q4: 📈 | S4: 🎯 | U4: 🌐 | W4: ✍🏻
D10: THE SUMMARY FORMULA
E14: {="📘 Summary of Filtered View: "&CHAR(10)&"📚 Total Books: "&'KPI CREATION'!M3:N3&CHAR(10)&"👤 Unique Authors: "&'KPI CREATION'!M6:N6&CHAR(10)&"🌏 Top Language: "&'KPI CREATION'!M15:N15&CHAR(10)&"🏆 Highest Rated Book: " &'KPI CREATION'!M12:N12&CHAR(10)&"⭐ Average Rating: " &ROUND('KPI CREATION'!M9:N9,1)&CHAR(10)&"📈 Most Popular Genre: " &'KPI CREATION'!M21:N21} -> 📘 Summary of Filtered View: 📚 Total Books: 1383 👤 Unique Authors: 11 🌏 Top Language: en 🏆 Highest Rated Book: Rich Dad Poor Dad ⭐ Average Rating: 0.6 📈 Most Popular Genre: Fiction | F14: 📘 Summary of Filtered View: 📚 Total Books: 👤 Unique Authors: 🌏 Top Language: 🏆 Highest Rated Book: ⭐ Average Rating: 0 📈 Most Popular Genre:

Sheet Book Insight - Dashboard
A1: BOOK INSIGHT EXPLORER: ANALYZING READER TRENDS AND GENRE PREFERENCES
